[2025-10-11T05:43:07.436+0200] {scheduler_job_runner.py:781} ERROR - Executor reports task instance <TaskInstance: predict_batch_dag.send_batch_predictions scheduled__2025-10-11T03:22:00+00:00 [queued]> finished (failed) although the task says it's queued. (Info: None) Was the task killed externally?
